<mujoco model="b1_description">
  <compiler angle="radian"/>

  <asset>
    <mesh name="trunkb" content_type="model/obj" file="meshes/trunkb.obj"/>
    <mesh name="hipb" content_type="model/obj" file="meshes/hipb.obj"/>
    <mesh name="thigh_mirrorb" content_type="model/obj" file="meshes/thigh_mirrorb.obj"/>
    <mesh name="calfb" content_type="model/obj" file="meshes/calfb.obj"/>
    <mesh name="thighb" content_type="model/obj" file="meshes/thighb.obj"/>
  </asset>

  <worldbody>
    <geom type="mesh" rgba="1 0.423529 0.0392157 1" mesh="trunkb"/>
    <geom size="0.0005 0.0005 0.0005" type="box" rgba="0.8 0 0 1"/>
    <geom size="0.05 0.01" pos="0.1955 -0.072 0" quat="0.707107 0 0.707107 0" type="cylinder" rgba="0 0.8 0 1"/>
    <geom size="0.05 0.01" pos="0.1955 0.072 0" quat="0.707107 0 0.707107 0" type="cylinder" rgba="0 0.8 0 1"/>
    <geom size="0.05 0.01" pos="-0.1955 -0.072 0" quat="0.707107 0 0.707107 0" type="cylinder" rgba="0 0.8 0 1"/>
    <geom size="0.05 0.01" pos="-0.1955 0.072 0" quat="0.707107 0 0.707107 0" type="cylinder" rgba="0 0.8 0 1"/>
    <body name="FR_hip" pos="0.3455 -0.072 0">
      <inertial pos="-0.0170338 -0.00868365 9.69992e-05" quat="0.510716 0.509633 0.489361 0.489867" mass="2.416" diaginertia="0.00991122 0.00677662 0.00456524"/>
      <joint name="FR_hip_joint" pos="0 0 0" axis="1 0 0" range="-0.75 0.75" actuatorfrcrange="-91.0035 91.0035"/>
      <geom quat="0 1 0 0" type="mesh" rgba="1 0.423529 0.0392157 1" mesh="hipb"/>
      <geom size="0.05 0.01" pos="0 -0.00935 0" quat="0.707107 0.707107 0 0" type="cylinder" rgba="0 0.8 0 1"/>
      <body name="FR_thigh" pos="0 -0.12675 0">
        <inertial pos="-0.00324483 0.0270318 -0.0510133" quat="0.677293 -0.0317048 0.0683476 0.731845" mass="4.566" diaginertia="0.0491815 0.0459436 0.00916385"/>
        <joint name="FR_thigh_joint" pos="0 0 0" axis="0 1 0" range="-1 3.5" actuatorfrcrange="-93.33 93.33"/>
        <geom type="mesh" rgba="1 0.423529 0.0392157 1" mesh="thigh_mirrorb"/>
        <geom size="0.05 0.01" pos="0 0.0519 0" quat="0.707107 0.707107 0 0" type="cylinder" rgba="0 0.8 0 1"/>
        <body name="FR_calf" pos="0 0 -0.35">
          <inertial pos="0.00499895 0 -0.209496" quat="0.707231 -0.0047996 -0.00482208 0.70695" mass="1.1" diaginertia="0.0162268 0.01608 0.000406156"/>
          <joint name="FR_calf_joint" pos="0 0 0" axis="0 1 0" range="-2.6 -0.6" actuatorfrcrange="-140 140"/>
          <geom type="mesh" rgba="1 0.423529 0.0392157 1" mesh="calfb"/>
          <geom size="0.04" pos="0 0 -0.35" rgba="0 0.8 0 1"/>
        </body>
      </body>
    </body>
    <body name="FL_hip" pos="0.3455 0.072 0">
      <inertial pos="-0.0190926 0.00868365 9.69992e-05" quat="0.487457 0.486787 0.511913 0.513195" mass="2.416" diaginertia="0.00973586 0.00659692 0.00456089"/>
      <joint name="FL_hip_joint" pos="0 0 0" axis="1 0 0" range="-0.75 0.75" actuatorfrcrange="-91.0035 91.0035"/>
      <geom type="mesh" rgba="1 0.423529 0.0392157 1" mesh="hipb"/>
      <geom size="0.05 0.01" pos="0 0.00935 0" quat="0.707107 0.707107 0 0" type="cylinder" rgba="0 0.8 0 1"/>
      <body name="FL_thigh" pos="0 0.12675 0">
        <inertial pos="0.00280221 -0.0270318 -0.0510133" quat="0.625018 0.0759054 -0.0297157 0.776343" mass="4.566" diaginertia="0.0493166 0.045984 0.00901283"/>
        <joint name="FL_thigh_joint" pos="0 0 0" axis="0 1 0" range="-1 3.5" actuatorfrcrange="-93.33 93.33"/>
        <geom type="mesh" rgba="1 0.423529 0.0392157 1" mesh="thighb"/>
        <geom size="0.05 0.01" pos="0 -0.0519 0" quat="0.707107 0.707107 0 0" type="cylinder" rgba="0 0.8 0 1"/>
        <body name="FL_calf" pos="0 0 -0.35">
          <inertial pos="0.00499895 0 -0.209496" quat="0.707231 -0.0047996 -0.00482208 0.70695" mass="1.1" diaginertia="0.0162268 0.01608 0.000406156"/>
          <joint name="FL_calf_joint" pos="0 0 0" axis="0 1 0" range="-2.6 -0.6" actuatorfrcrange="-140 140"/>
          <geom type="mesh" rgba="1 0.423529 0.0392157 1" mesh="calfb"/>
          <geom size="0.04" pos="0 0 -0.35" rgba="0 0.8 0 1"/>
        </body>
      </body>
    </body>
    <body name="RR_hip" pos="-0.3455 -0.072 0">
      <inertial pos="0.0190926 -0.00868365 9.69992e-05" quat="0.486787 0.487457 0.513195 0.511913" mass="2.416" diaginertia="0.00973586 0.00659692 0.00456089"/>
      <joint name="RR_hip_joint" pos="0 0 0" axis="1 0 0" range="-0.75 0.75" actuatorfrcrange="-91.0035 91.0035"/>
      <geom quat="0 0 0 -1" type="mesh" rgba="1 0.423529 0.0392157 1" mesh="hipb"/>
      <geom size="0.05 0.01" pos="0 -0.00935 0" quat="0.707107 0.707107 0 0" type="cylinder" rgba="0 0.8 0 1"/>
      <body name="RR_thigh" pos="0 -0.12675 0">
        <inertial pos="-0.00324483 0.0270318 -0.0510133" quat="0.677293 -0.0317048 0.0683476 0.731845" mass="4.566" diaginertia="0.0491815 0.0459436 0.00916385"/>
        <joint name="RR_thigh_joint" pos="0 0 0" axis="0 1 0" range="-1 3.5" actuatorfrcrange="-93.33 93.33"/>
        <geom type="mesh" rgba="1 0.423529 0.0392157 1" mesh="thigh_mirrorb"/>
        <geom size="0.05 0.01" pos="0 0.0519 0" quat="0.707107 0.707107 0 0" type="cylinder" rgba="0 0.8 0 1"/>
        <body name="RR_calf" pos="0 0 -0.35">
          <inertial pos="0.00499895 0 -0.209496" quat="0.707231 -0.0047996 -0.00482208 0.70695" mass="1.1" diaginertia="0.0162268 0.01608 0.000406156"/>
          <joint name="RR_calf_joint" pos="0 0 0" axis="0 1 0" range="-2.6 -0.6" actuatorfrcrange="-140 140"/>
          <geom type="mesh" rgba="1 0.423529 0.0392157 1" mesh="calfb"/>
          <geom size="0.04" pos="0 0 -0.35" rgba="0 0.8 0 1"/>
        </body>
      </body>
    </body>
    <body name="RL_hip" pos="-0.3455 0.072 0">
      <inertial pos="0.0170338 0.00868365 9.69992e-05" quat="0.509633 0.510716 0.489867 0.489361" mass="2.416" diaginertia="0.00991122 0.00677662 0.00456524"/>
      <joint name="RL_hip_joint" pos="0 0 0" axis="1 0 0" range="-0.75 0.75" actuatorfrcrange="-91.0035 91.0035"/>
      <geom quat="0 0 1 0" type="mesh" rgba="1 0.423529 0.0392157 1" mesh="hipb"/>
      <geom size="0.05 0.01" pos="0 0.00935 0" quat="0.707107 0.707107 0 0" type="cylinder" rgba="0 0.8 0 1"/>
      <body name="RL_thigh" pos="0 0.12675 0">
        <inertial pos="0.00280221 -0.0270318 -0.0510133" quat="0.625018 0.0759054 -0.0297157 0.776343" mass="4.566" diaginertia="0.0493166 0.045984 0.00901283"/>
        <joint name="RL_thigh_joint" pos="0 0 0" axis="0 1 0" range="-1 3.5" actuatorfrcrange="-93.33 93.33"/>
        <geom type="mesh" rgba="1 0.423529 0.0392157 1" mesh="thighb"/>
        <geom size="0.05 0.01" pos="0 -0.0519 0" quat="0.707107 0.707107 0 0" type="cylinder" rgba="0 0.8 0 1"/>
        <body name="RL_calf" pos="0 0 -0.35">
          <inertial pos="0.00499895 0 -0.209496" quat="0.707231 -0.0047996 -0.00482208 0.70695" mass="1.1" diaginertia="0.0162268 0.01608 0.000406156"/>
          <joint name="RL_calf_joint" pos="0 0 0" axis="0 1 0" range="-2.6 -0.6" actuatorfrcrange="-140 140"/>
          <geom type="mesh" rgba="1 0.423529 0.0392157 1" mesh="calfb"/>
          <geom size="0.04" pos="0 0 -0.35" rgba="0 0.8 0 1"/>
        </body>
      </body>
    </body>
  </worldbody>
</mujoco>
