<?xml version="1.0" ?>
<robot name="z1">

    <material name="Grey">
        <color rgba="0.3 0.3 0.3 1.0" />
    </material>

    <link name="world" />

    <joint name="base_static_joint" type="fixed">
        <origin rpy="0 0 0" xyz="0 0 0" />
        <parent link="world" />
        <child link="link00" />
    </joint>

    <link name="link00">
        <visual>
            <origin rpy="0 0 0" xyz="0 0 0" />
            <geometry>
                <mesh filename="meshes/z1_Link00.STL" scale="1 1 1" />
            </geometry>
            <material name="Grey" />
        </visual>
        <collision>
            <geometry>
                <mesh filename="meshes/z1_Link00.STL" scale="1 1 1" />
            </geometry>
            <origin rpy="0 0 0" xyz="0 0 0.0255" />
        </collision>
        <inertial>
            <origin rpy="0 0 0" xyz="-0.00334984 -0.00013615 0.02495843" />
            <mass value="0.47247481" />
            <inertia
                ixx="0.00037937" ixy="-0.00000035" ixz="-0.00001037"
                iyy="0.00041521" iyz="-0.00000099"
                izz="0.00053066" />
        </inertial>
    </link>

    <joint name="joint1" type="revolute">
        <origin rpy="0 0 0" xyz="0 0 0.0585" />
        <parent link="link00" />
        <child link="link01" />
        <axis xyz="0 0 1" />
        <dynamics damping="1.0" friction="1.0" />
        <limit effort="30.0" velocity="3.1415" lower="-2.61799" upper="2.61799" />
    </joint>

    <link name="link01">
        <visual>
            <origin rpy="0 0 0" xyz="0 0 0" />
            <geometry>
                <mesh filename="meshes/z1_Link01.STL" scale="1 1 1" />
            </geometry>
            <material name="Grey" />
        </visual>
        <collision>
            <geometry>
                <mesh filename="meshes/z1_Link01.STL" scale="1 1 1" />
            </geometry>
        </collision>
        <inertial>
            <origin rpy="0 0 0" xyz="0.00000247 -0.00025198 0.02317169" />
            <mass value="0.67332551" />
            <inertia
                ixx="0.00128328" ixy="-0.00000006" ixz="-0.00000040"
                iyy="0.00071931" iyz="0.00000050"
                izz="0.00083936" />
        </inertial>
    </link>

    <joint name="joint2" type="revolute">
        <origin rpy="0 0 0" xyz="0 0 0.045" />
        <parent link="link01" />
        <child link="link02" />
        <axis xyz="0 1 0" />
        <dynamics damping="2.0" friction="2.0" />
        <limit effort="60.0" velocity="3.1415" lower="0.0" upper="2.96706" />
    </joint>

    <link name="link02">
        <visual>
            <origin rpy="0 0 0" xyz="0 0 0" />
            <geometry>
                <mesh filename="meshes/z1_Link02.STL" scale="1 1 1" />
            </geometry>
            <material name="Grey" />
        </visual>
        <collision>
            <geometry>
                <mesh filename="meshes/z1_Link02.STL" scale="1 1 1" />
            </geometry>
        </collision>
        <inertial>
            <origin rpy="0 0 0" xyz="-0.11012601 0.00240029 0.00158266" />
            <mass value="1.19132258" />
            <inertia
                ixx="0.00102138" ixy="0.00062358" ixz="0.00000513"
                iyy="0.02429457" iyz="-0.00000210"
                izz="0.02466114" />
        </inertial>
    </link>

    <joint name="joint3" type="revolute">
        <origin rpy="0 0 0" xyz="-0.35 0 0" />
        <parent link="link02" />
        <child link="link03" />
        <axis xyz="0 1 0" />
        <dynamics damping="1.0" friction="1.0" />
        <limit effort="30.0" velocity="3.1415" lower="-2.87979" upper="0.0" />
    </joint>

    <link name="link03">
        <visual>
            <origin rpy="0 0 0" xyz="0 0 0" />
            <geometry>
                <mesh filename="meshes/z1_Link03.STL" scale="1 1 1" />
            </geometry>
            <material name="Grey" />
        </visual>
        <collision>
            <geometry>
                <mesh filename="meshes/z1_Link03.STL" scale="1 1 1" />
            </geometry>
        </collision>
        <inertial>
            <origin rpy="0 0 0" xyz="0.10609208 -0.00541815 0.03476383" />
            <mass value="0.83940874" />
            <inertia
                ixx="0.00108061" ixy="-0.00008669" ixz="-0.00208102"
                iyy="0.00954238" iyz="-0.00001332"
                izz="0.00886621" />
        </inertial>
    </link>

    <joint name="joint4" type="revolute">
        <origin rpy="0 0 0" xyz="0.218 0 0.057" />
        <parent link="link03" />
        <child link="link04" />
        <axis xyz="0 1 0" />
        <dynamics damping="1.0" friction="1.0" />
        <limit effort="30.0" velocity="3.1415" lower="-1.51844" upper="1.51844" />
    </joint>

    <link name="link04">
        <visual>
            <origin rpy="0 0 0" xyz="0 0 0" />
            <geometry>
                <mesh filename="meshes/z1_Link04.STL" scale="1 1 1" />
            </geometry>
            <material name="Grey" />
        </visual>
        <collision>
            <geometry>
                <mesh filename="meshes/z1_Link04.STL" scale="1 1 1" />
            </geometry>
        </collision>
        <inertial>
            <origin rpy="0 0 0" xyz="0.04366681 0.00364738 -0.00170192" />
            <mass value="0.56404563" />
            <inertia
                ixx="0.00031576" ixy="0.00008130" ixz="0.00004091"
                iyy="0.00092996" iyz="-0.00000596"
                izz="0.00097912" />
        </inertial>
    </link>

    <joint name="joint5" type="revolute">
        <origin rpy="0 0 0" xyz="0.07 0.0 0.0" />
        <parent link="link04" />
        <child link="link05" />
        <axis xyz="0 0 1" />
        <dynamics damping="1.0" friction="1.0" />
        <limit effort="30.0" velocity="3.1415" lower="-1.34390" upper="1.34390" />
    </joint>

    <link name="link05">
        <visual>
            <origin rpy="0 0 0" xyz="0 0 0" />
            <geometry>
                <mesh filename="meshes/z1_Link05.STL" scale="1 1 1" />
            </geometry>
            <material name="Grey" />
        </visual>
        <collision>
            <geometry>
                <mesh filename="meshes/z1_Link05.STL" scale="1 1 1" />
            </geometry>
        </collision>
        <inertial>
            <origin rpy="0 0 0" xyz="0.03121533 0.0 0.00646316" />
            <mass value="0.38938492" />
            <inertia
                ixx="0.00017605" ixy="0.00000040" ixz="0.00005689"
                iyy="0.00055896" iyz="-0.00000013"
                izz="0.00053860" />
        </inertial>
    </link>

    <joint name="joint6" type="revolute">
        <origin rpy="0 0 0" xyz="0.0492 0.0 0.0" />
        <parent link="link05" />
        <child link="link06" />
        <axis xyz="1 0 0" />
        <dynamics damping="1.0" friction="1.0" />
        <limit effort="30.0" velocity="3.1415" lower="-2.79253" upper="2.79253" />
    </joint>

    <link name="link06">
        <visual>
            <origin rpy="0 0 0" xyz="0 0 0" />
            <geometry>
                <mesh filename="meshes/z1_Link06.STL" scale="1 1 1" />
            </geometry>
            <material name="Grey" />
        </visual>
        <collision>
            <geometry>
                <mesh filename="meshes/z1_Link06.STL" scale="1 1 1" />
            </geometry>
        </collision>
        <inertial>
            <origin rpy="0 0 0" xyz="0.02415690 -0.00017355 -0.00143876" />
            <mass value="0.28875807" />
            <inertia
                ixx="0.00018328" ixy="0.00000122" ixz="0.00000054"
                iyy="0.00014750" iyz="0.00000008"
                izz="0.00014680" />
        </inertial>
    </link>

    <joint name="gripperStatorLink" type="fixed">
        <origin rpy="0 0 0" xyz="0.051 0.0 0.0" />
        <parent link="link06" />
        <child link="gripperStator" />
    </joint>

    <link name="gripperStator">
        <visual>
            <geometry>
                <mesh filename="meshes/z1_GripperStator.STL" scale="1 1 1" />
            </geometry>
            <material name="Grey" />
        </visual>
        <collision>
            <geometry>
                <mesh filename="meshes/z1_GripperStator.STL" scale="1 1 1" />
            </geometry>
        </collision>
        <inertial>
            <origin rpy="0 0 0" xyz="0.04764427 -0.00035819 -0.00249162" />
            <mass value="0.52603655" />
            <inertia
                ixx="0.00038683" ixy="-0.00000359" ixz="0.00007662"
                iyy="0.00068614" iyz="0.00000209"
                izz="0.00066293" />
        </inertial>
    </link>

    <joint name="jointGripper" type="revolute">
        <origin rpy="0 0 0" xyz="0.049 0.0 0" />
        <parent link="gripperStator" />
        <child link="gripperMover" />
        <axis xyz="0 1 0" />
        <dynamics damping="1.0" friction="1.0" />
        <limit effort="30.0" velocity="3.1415" lower="-1.5708" upper="0.0" />
    </joint>

    <link name="gripperMover">
        <visual>
            <geometry>
                <mesh filename="meshes/z1_GripperMover.STL" scale="1 1 1" />
            </geometry>
            <material name="Grey" />
        </visual>
        <collision>
            <geometry>
                <mesh filename="meshes/z1_GripperMover.STL" scale="1 1 1" />
            </geometry>
        </collision>
        <inertial>
            <origin rpy="0 0 0" xyz="0.01320633 0.00476708 0.00380534" />
            <mass value="0.27621302" />
            <inertia
                ixx="0.00017716" ixy="0.00001683" ixz="-0.00001786"
                iyy="0.00026787" iyz="0.00000262"
                izz="0.00035728" />
        </inertial>
    </link>

    <gazebo reference="gripperStator">
        <self_collide>true</self_collide>
    </gazebo>

    <gazebo reference="gripperMover">
        <self_collide>true</self_collide>
    </gazebo>

    <gazebo reference="world" />
    <gazebo>
        <plugin filename="libign_ros2_control-system.so" name="ign_ros2_control::IgnitionROS2ControlPlugin">
            <parameters> $(find z1_bringup)/config/z1_controllers.yaml </parameters>
            <robot_param> robot_description </robot_param>
            <robot_param_node> robot_state_publisher </robot_param_node>
            <controller_manager_name> controller_manager </controller_manager_name>
        </plugin>
    </gazebo>

    <ros2_control name="z1" type="system">
        <hardware>
            <plugin>ign_ros2_control/IgnitionSystem</plugin>
        </hardware>

        <joint name="joint1">
            <command_interface name="position">
                <param name="min"> -2.61799 </param>
                <param name="max"> 2.61799 </param>
            </command_interface>
            <command_interface name="effort">
                <param name="min"> -30.0 </param>
                <param name="max"> 30.0 </param>
            </command_interface>
            <state_interface name="position" />
            <state_interface name="velocity" />
            <state_interface name="effort" />
        </joint>

        <joint name="joint2">
            <command_interface name="position">
                <param name="min"> 0.0 </param>
                <param name="max"> 2.96706 </param>
            </command_interface>
            <command_interface name="effort">
                <param name="min"> -30.0 </param>
                <param name="max"> 30.0 </param>
            </command_interface>
            <state_interface name="position">
                <param name="initial_value">1.57</param>
            </state_interface>
            <state_interface name="velocity" />
            <state_interface name="effort" />
        </joint>

        <joint name="joint3">
            <command_interface name="position">
                <param name="min"> -2.87979 </param>
                <param name="max"> 0.0 </param>
            </command_interface>
            <command_interface name="effort">
                <param name="min"> -30.0 </param>
                <param name="max"> 30.0 </param>
            </command_interface>
            <state_interface name="position">
                <param name="initial_value">-1.57</param>
            </state_interface>
            <state_interface name="velocity" />
            <state_interface name="effort" />
        </joint>

        <joint name="joint4">
            <command_interface name="position">
                <param name="min"> -1.51844 </param>
                <param name="max"> 1.51844 </param>
            </command_interface>
            <command_interface name="effort">
                <param name="min"> -30.0 </param>
                <param name="max"> 30.0 </param>
            </command_interface>
            <state_interface name="position" />
            <state_interface name="velocity" />
            <state_interface name="effort" />
        </joint>

        <joint name="joint5">
            <command_interface name="position">
                <param name="min"> -1.34390 </param>
                <param name="max"> 1.34390 </param>
            </command_interface>
            <command_interface name="effort">
                <param name="min"> -30.0 </param>
                <param name="max"> 30.0 </param>
            </command_interface>
            <state_interface name="position" />
            <state_interface name="velocity" />
            <state_interface name="effort" />
        </joint>

        <joint name="joint6">
            <command_interface name="position">
                <param name="min"> -2.79253 </param>
                <param name="max"> 2.79253 </param>
            </command_interface>
            <command_interface name="effort">
                <param name="min"> -30.0 </param>
                <param name="max"> 30.0 </param>
            </command_interface>
            <state_interface name="position" />
            <state_interface name="velocity" />
            <state_interface name="effort" />
        </joint>

        <joint name="jointGripper">
            <command_interface name="position">
                <param name="min"> -1.5708 </param>
                <param name="max"> 0.0 </param>
            </command_interface>
            <command_interface name="effort">
                <param name="min"> -30.0 </param>
                <param name="max"> 30.0 </param>
            </command_interface>
            <state_interface name="position" />
            <state_interface name="velocity" />
            <state_interface name="effort" />
        </joint>
    </ros2_control>

</robot>
